<?xml version="1.0" ?>
<robot name="industrial" xmlns:xacro="http://www.ros.org/wiki/xacro">

<xacro:include filename="$(find industrial_description)/urdf/materials.xacro" />
<xacro:include filename="$(find industrial_description)/urdf/industrial.trans" />
<xacro:include filename="$(find industrial_description)/urdf/industrial.gazebo" />
<link name="base_link">
  <inertial>
    <origin xyz="0.2548338399011842 0.039363954343754844 0.31001749808238654" rpy="0 0 0"/>
    <mass value="45.31428377967853"/>
    <inertia ixx="0.286619" iyy="0.523195" izz="0.286478" ixy="-0.000299" iyz="0.000324" ixz="-0.006278"/>
  </inertial>
  <visual>
    <origin xyz="0 0 0" rpy="0 0 0"/>
    <geometry>
      <mesh filename="package://industrial_description/meshes/base_link.stl" scale="0.001 0.001 0.001"/>
    </geometry>
    <material name="paint_metallic_black"/>
  </visual>
  <collision>
    <origin xyz="0 0 0" rpy="0 0 0"/>
    <geometry>
      <mesh filename="package://industrial_description/meshes/base_link.stl" scale="0.001 0.001 0.001"/>
    </geometry>
  </collision>
</link>

<link name="JAW_1_1">
  <inertial>
    <origin xyz="-0.059246619323310074 0.08495449970422884 0.003876432288686338" rpy="0 0 0"/>
    <mass value="18.75878094663069"/>
    <inertia ixx="0.097637" iyy="0.132376" izz="0.194071" ixy="0.074393" iyz="-0.004334" ixz="0.004819"/>
  </inertial>
  <visual>
    <origin xyz="-0.253392 -0.084654 -0.311443" rpy="0 0 0"/>
    <geometry>
      <mesh filename="package://industrial_description/meshes/JAW_1_1.stl" scale="0.001 0.001 0.001"/>
    </geometry>
    <material name="steel_satin"/>
  </visual>
  <collision>
    <origin xyz="-0.253392 -0.084654 -0.311443" rpy="0 0 0"/>
    <geometry>
      <mesh filename="package://industrial_description/meshes/JAW_1_1.stl" scale="0.001 0.001 0.001"/>
    </geometry>
  </collision>
</link>

<link name="JAW_2_1">
  <inertial>
    <origin xyz="0.10451597593488317 0.0926934587697287 -0.015603834274600659" rpy="0 0 0"/>
    <mass value="6.328442247675211"/>
    <inertia ixx="0.065903" iyy="0.071298" izz="0.135195" ixy="-0.06454" iyz="-0.000178" ixz="-0.000489"/>
  </inertial>
  <visual>
    <origin xyz="-0.103425 -0.244808 -0.291223" rpy="0 0 0"/>
    <geometry>
      <mesh filename="package://industrial_description/meshes/JAW_2_1.stl" scale="0.001 0.001 0.001"/>
    </geometry>
    <material name="steel_satin"/>
  </visual>
  <collision>
    <origin xyz="-0.103425 -0.244808 -0.291223" rpy="0 0 0"/>
    <geometry>
      <mesh filename="package://industrial_description/meshes/JAW_2_1.stl" scale="0.001 0.001 0.001"/>
    </geometry>
  </collision>
</link>

<link name="JAW_3_1">
  <inertial>
    <origin xyz="-0.04842956677440935 0.0339771945754212 0.046283489142288026" rpy="0 0 0"/>
    <mass value="11.40386436403121"/>
    <inertia ixx="0.015199" iyy="0.064243" izz="0.067337" ixy="-0.002718" iyz="-0.000888" ixz="0.000845"/>
  </inertial>
  <visual>
    <origin xyz="-0.353593 -0.489585 -0.291634" rpy="0 0 0"/>
    <geometry>
      <mesh filename="package://industrial_description/meshes/JAW_3_1.stl" scale="0.001 0.001 0.001"/>
    </geometry>
    <material name="steel_satin"/>
  </visual>
  <collision>
    <origin xyz="-0.353593 -0.489585 -0.291634" rpy="0 0 0"/>
    <geometry>
      <mesh filename="package://industrial_description/meshes/JAW_3_1.stl" scale="0.001 0.001 0.001"/>
    </geometry>
  </collision>
</link>

<link name="JAW_4_1">
  <inertial>
    <origin xyz="-0.06679268105117524 -0.007650782836484127 0.0003458632493384406" rpy="0 0 0"/>
    <mass value="3.736976429844003"/>
    <inertia ixx="0.003209" iyy="0.009402" izz="0.008957" ixy="-0.000719" iyz="4e-06" ixz="-5e-06"/>
  </inertial>
  <visual>
    <origin xyz="-0.103992 -0.506311 -0.339224" rpy="0 0 0"/>
    <geometry>
      <mesh filename="package://industrial_description/meshes/JAW_4_1.stl" scale="0.001 0.001 0.001"/>
    </geometry>
    <material name="steel_satin"/>
  </visual>
  <collision>
    <origin xyz="-0.103992 -0.506311 -0.339224" rpy="0 0 0"/>
    <geometry>
      <mesh filename="package://industrial_description/meshes/JAW_4_1.stl" scale="0.001 0.001 0.001"/>
    </geometry>
  </collision>
</link>

<link name="JAW_5_1">
  <inertial>
    <origin xyz="-0.049700553139761655 -0.031801725366641886 0.011526286038185563" rpy="0 0 0"/>
    <mass value="2.672375979830758"/>
    <inertia ixx="0.002209" iyy="0.002555" izz="0.002819" ixy="-0.000372" iyz="1.1e-05" ixz="1.7e-05"/>
  </inertial>
  <visual>
    <origin xyz="0.010253 -0.493343 -0.326537" rpy="0 0 0"/>
    <geometry>
      <mesh filename="package://industrial_description/meshes/JAW_5_1.stl" scale="0.001 0.001 0.001"/>
    </geometry>
    <material name="steel_satin"/>
  </visual>
  <collision>
    <origin xyz="0.010253 -0.493343 -0.326537" rpy="0 0 0"/>
    <geometry>
      <mesh filename="package://industrial_description/meshes/JAW_5_1.stl" scale="0.001 0.001 0.001"/>
    </geometry>
  </collision>
</link>

<link name="JAW_6_1">
  <inertial>
    <origin xyz="-0.013775380389767819 -0.008785724302981801 -8.748866270125166e-05" rpy="0 0 0"/>
    <mass value="0.600174321482272"/>
    <inertia ixx="0.000303" iyy="0.000284" izz="0.000281" ixy="2e-05" iyz="2e-05" ixz="-1.2e-05"/>
  </inertial>
  <visual>
    <origin xyz="0.089511 -0.442687 -0.338032" rpy="0 0 0"/>
    <geometry>
      <mesh filename="package://industrial_description/meshes/JAW_6_1.stl" scale="0.001 0.001 0.001"/>
    </geometry>
    <material name="paint_metallic_black"/>
  </visual>
  <collision>
    <origin xyz="0.089511 -0.442687 -0.338032" rpy="0 0 0"/>
    <geometry>
      <mesh filename="package://industrial_description/meshes/JAW_6_1.stl" scale="0.001 0.001 0.001"/>
    </geometry>
  </collision>
</link>

<link name="JAW_7__2__1">
  <inertial>
    <origin xyz="-0.03852995296871463 -0.027898058341137955 -0.010161505028423945" rpy="0 0 0"/>
    <mass value="0.2441632396754522"/>
    <inertia ixx="7.9e-05" iyy="0.000161" izz="0.000221" ixy="-9.1e-05" iyz="3e-06" ixz="-1e-06"/>
  </inertial>
  <visual>
    <origin xyz="0.103562 -0.403223 -0.370795" rpy="0 0 0"/>
    <geometry>
      <mesh filename="package://industrial_description/meshes/JAW_7__2__1.stl" scale="0.001 0.001 0.001"/>
    </geometry>
    <material name="paint_metallic_black"/>
  </visual>
  <collision>
    <origin xyz="0.103562 -0.403223 -0.370795" rpy="0 0 0"/>
    <geometry>
      <mesh filename="package://industrial_description/meshes/JAW_7__2__1.stl" scale="0.001 0.001 0.001"/>
    </geometry>
  </collision>
</link>

<link name="JAW_7_1">
  <inertial>
    <origin xyz="-0.02553781863191204 -0.04089139374660061 0.004945214888827543" rpy="0 0 0"/>
    <mass value="0.24576959229480003"/>
    <inertia ixx="0.00013" iyy="0.000118" izz="0.000215" ixy="-9.7e-05" iyz="3e-05" ixz="2.4e-05"/>
  </inertial>
  <visual>
    <origin xyz="0.137153 -0.456407 -0.318789" rpy="0 0 0"/>
    <geometry>
      <mesh filename="package://industrial_description/meshes/JAW_7_1.stl" scale="0.001 0.001 0.001"/>
    </geometry>
    <material name="paint_metallic_black"/>
  </visual>
  <collision>
    <origin xyz="0.137153 -0.456407 -0.318789" rpy="0 0 0"/>
    <geometry>
      <mesh filename="package://industrial_description/meshes/JAW_7_1.stl" scale="0.001 0.001 0.001"/>
    </geometry>
  </collision>
</link>

<joint name="Rev1" type="continuous">
  <origin xyz="0.253392 0.084654 0.311443" rpy="0 0 0"/>
  <parent link="base_link"/>
  <child link="JAW_1_1"/>
  <axis xyz="0.0 1.0 -0.0"/>
</joint>

<joint name="Rev2" type="continuous">
  <origin xyz="-0.149967 0.160154 -0.02022" rpy="0 0 0"/>
  <parent link="JAW_1_1"/>
  <child link="JAW_2_1"/>
  <axis xyz="0.001642 0.0 -0.999999"/>
</joint>

<joint name="Rev3" type="continuous">
  <origin xyz="0.250168 0.244777 0.000411" rpy="0 0 0"/>
  <parent link="JAW_2_1"/>
  <child link="JAW_3_1"/>
  <axis xyz="-0.001642 -0.0 0.999999"/>
</joint>

<joint name="Rev4" type="continuous">
  <origin xyz="-0.249601 0.016726 0.04759" rpy="0 0 0"/>
  <parent link="JAW_3_1"/>
  <child link="JAW_4_1"/>
  <axis xyz="-0.993508 -0.113747 -0.001632"/>
</joint>

<joint name="Rev5" type="continuous">
  <origin xyz="-0.114245 -0.012968 -0.012687" rpy="0 0 0"/>
  <parent link="JAW_4_1"/>
  <child link="JAW_5_1"/>
  <axis xyz="-0.00061 -0.009017 0.999959"/>
</joint>

<joint name="Rev6" type="continuous">
  <origin xyz="-0.079258 -0.050656 0.011495" rpy="0 0 0"/>
  <parent link="JAW_5_1"/>
  <child link="JAW_6_1"/>
  <axis xyz="-0.843092 -0.537743 -0.005363"/>
</joint>

<joint name="Rev7" type="continuous">
  <origin xyz="-0.014051 -0.039464 0.032763" rpy="0 0 0"/>
  <parent link="JAW_6_1"/>
  <child link="JAW_7__2__1"/>
  <axis xyz="0.346139 -0.535002 -0.770689"/>
</joint>

<joint name="Rev8" type="continuous">
  <origin xyz="-0.047642 0.01372 -0.019243" rpy="0 0 0"/>
  <parent link="JAW_6_1"/>
  <child link="JAW_7_1"/>
  <axis xyz="0.346139 -0.535002 -0.770689"/>
</joint>

</robot>
